<?xml version="1.0" ?>
<sdf version="1.4">
    <world name="default">
        <plugin name="SimpleWorldController" filename="libSimpleWorldController.so" />
        <!-- Ground Plane -->
        <include>
            <uri>model://ground_plane</uri>
        </include>
        <include>
            <uri>model://sun</uri>
        </include>
        <model name="box">
            <pose>0 0 0 0 0 0</pose>
            <link name="link">
                <pose>0 0 0.5 0 0 0</pose>
                <collision name="collision">
                    <geometry>
                        <box>
                            <size>1 1 1</size>
                        </box>
                    </geometry>
                </collision>
                <visual name="visual">
                    <geometry>
                        <box>
                            <size>1 1 1</size>
                        </box>
                    </geometry>
                </visual>
                <inertial>
                    <mass>100.0</mass>
                    <pose>0 0 0 0 0 0</pose>
                    <inertia>
                        <ixx>0.1</ixx>
                        <iyy>0.1</iyy>
                        <izz>0.1</izz>
                        <ixy>0.1</ixy>
                        <ixz>0.1</ixz>
                        <iyz>0.1</iyz>
                    </inertia>
                </inertial>
            </link>
            <link name="link2">
                <pose>1.0 0 1.5 0 0 0</pose>
                <collision name="collision">
                    <geometry>
                        <box>
                            <size>1 1 1</size>
                        </box>
                    </geometry>
                </collision>
                <visual name="visual">
                    <geometry>
                        <box>
                            <size>1 1 1</size>
                        </box>
                    </geometry>
                </visual>
                <inertial>
                    <mass>5.0</mass>
                    <pose>0 0 0 0 0 0</pose>
                    <inertia>
                        <ixx>0.1</ixx>
                        <iyy>0.1</iyy>
                        <izz>0.1</izz>
                        <ixy>0.1</ixy>
                        <ixz>0.1</ixz>
                        <iyz>0.1</iyz>
                    </inertia>
                </inertial>
            </link>
            <link name="link3">
                <pose>2.0 0 2.5 0 0 0</pose>
                <collision name="collision">
                    <geometry>
                        <box>
                            <size>1 1 1</size>
                        </box>
                    </geometry>
                </collision>
                <visual name="visual">
                    <geometry>
                        <box>
                            <size>1 1 1</size>
                        </box>
                    </geometry>
                </visual>
                <inertial>
                    <mass>1.0</mass>
                    <pose>0 0 0 0 0 0</pose>
                    <inertia>
                        <ixx>0.1</ixx>
                        <iyy>0.1</iyy>
                        <izz>0.1</izz>
                        <ixy>0.1</ixy>
                        <ixz>0.1</ixz>
                        <iyz>0.1</iyz>
                    </inertia>
                </inertial>
            </link>
            <joint name="joint1" type="revolute">
                <pose>-0.5 0 -0.5 0 0 0</pose>
                <physics>
                    <ode>
                        <provide_feedback>true</provide_feedback>
                    </ode>
                </physics>
                <axis>
                    <xyz>0 1 0</xyz>
                </axis>
                <parent>
                    <link_name>link</link_name>
                </parent>
                <child>
                    <link_name>link2</link_name>
                </child>
            </joint>
            <joint name="joint2" type="revolute">
                <pose>-0.5 0 -0.5 0 0 0</pose>
                <physics>
                    <ode>
                        <provide_feedback>true</provide_feedback>
                    </ode>
                </physics>
                <axis>
                    <xyz>0 1 0</xyz>
                </axis>
                <parent>
                    <link_name>link2</link_name>
                </parent>
                <child>
                    <link_name>link3</link_name>
                </child>
            </joint>
            <!--<plugin name="GazeboJointControlTester" filename="libGazeboJointControlTester.so">
      </plugin>-->
            <plugin name="GazeboStateCommunicator" filename="libGazeboStateCommunicator.so" imulink="imu_link" />
        </model>
        <physics type="ode">
            <gravity>0.000000 0.000000 -9.800000</gravity>
            <ode>
                <solver>
                    <iters>1500</iters>
                </solver>
            </ode>
            <real_time_update_rate>10000.000000</real_time_update_rate>
            <max_step_size>0.0001</max_step_size>
        </physics>
    </world>
</sdf>
